时间:2020-05-14 01:06:59.512
级别:error
来源:ApiExceptionHandleMiddleware
消息:这是一个测试异常
异常:Message:这是一个测试异常.Description:System.Exception: 这是一个测试异常
   at Hzdtf.WebTest3._1.Core.Controllers.DefaultController.Get() in C:\AndyData\MyProject\Hzdtf.FoundationFramework\WebDemoCore\Hzdtf.WebTest3.1.Core\Controllers\DefaultController.cs:line 18
   at lambda_method(Closure , Object , Object[] )
   at Microsoft.Extensions.Internal.ObjectMethodExecutor.Execute(Object target, Object[] parameters)
   at Microsoft.AspNetCore.Mvc.Infrastructure.ActionMethodExecutor.SyncObjectResultExecutor.Execute(IActionResultTypeMapper mapper, ObjectMethodExecutor executor, Object controller, Object[] arguments)
   at Microsoft.AspNetCore.Mvc.Infrastructure.ControllerActionInvoker.InvokeActionMethodAsync()
   at Microsoft.AspNetCore.Mvc.Infrastructure.ControllerActionInvoker.Next(State& next, Scope& scope, Object& state, Boolean& isCompleted)
   at Microsoft.AspNetCore.Mvc.Infrastructure.ControllerActionInvoker.InvokeNextActionFilterAsync()
--- End of stack trace from previous location where exception was thrown ---
   at Microsoft.AspNetCore.Mvc.Infrastructure.ControllerActionInvoker.Rethrow(ActionExecutedContextSealed context)
   at Microsoft.AspNetCore.Mvc.Infrastructure.ControllerActionInvoker.Next(State& next, Scope& scope, Object& state, Boolean& isCompleted)
   at Microsoft.AspNetCore.Mvc.Infrastructure.ControllerActionInvoker.InvokeInnerFilterAsync()
--- End of stack trace from previous location where exception was thrown ---
   at Microsoft.AspNetCore.Mvc.Infrastructure.ResourceInvoker.<InvokeFilterPipelineAsync>g__Awaited|19_0(ResourceInvoker invoker, Task lastTask, State next, Scope scope, Object state, Boolean isCompleted)
   at Microsoft.AspNetCore.Mvc.Infrastructure.ResourceInvoker.<InvokeAsync>g__Awaited|17_0(ResourceInvoker invoker, Task task, IDisposable scope)
   at Microsoft.AspNetCore.Routing.EndpointMiddleware.<Invoke>g__AwaitRequestTask|6_0(Endpoint endpoint, Task requestTask, ILogger logger)
   at Hzdtf.Utility.AspNet.Core.ExceptionHandle.ApiExceptionHandleMiddleware.InvokeAsync(HttpContext context) in C:\AndyData\MyProject\Hzdtf.FoundationFramework\Common\Hzdtf.Utility.AspNet.Core\ExceptionHandle\ApiExceptionHandleMiddleware.cs:line 59
时间:2020-05-14 01:08:40.037
级别:error
来源:ApiExceptionHandleMiddleware
消息:这是一个测试异常
异常:Message:这是一个测试异常.Description:System.Exception: 这是一个测试异常
   at Hzdtf.WebTest3._1.Core.Controllers.DefaultController.Get() in C:\AndyData\MyProject\Hzdtf.FoundationFramework\WebDemoCore\Hzdtf.WebTest3.1.Core\Controllers\DefaultController.cs:line 18
   at lambda_method(Closure , Object , Object[] )
   at Microsoft.Extensions.Internal.ObjectMethodExecutor.Execute(Object target, Object[] parameters)
   at Microsoft.AspNetCore.Mvc.Infrastructure.ActionMethodExecutor.SyncObjectResultExecutor.Execute(IActionResultTypeMapper mapper, ObjectMethodExecutor executor, Object controller, Object[] arguments)
   at Microsoft.AspNetCore.Mvc.Infrastructure.ControllerActionInvoker.InvokeActionMethodAsync()
   at Microsoft.AspNetCore.Mvc.Infrastructure.ControllerActionInvoker.Next(State& next, Scope& scope, Object& state, Boolean& isCompleted)
   at Microsoft.AspNetCore.Mvc.Infrastructure.ControllerActionInvoker.InvokeNextActionFilterAsync()
--- End of stack trace from previous location where exception was thrown ---
   at Microsoft.AspNetCore.Mvc.Infrastructure.ControllerActionInvoker.Rethrow(ActionExecutedContextSealed context)
   at Microsoft.AspNetCore.Mvc.Infrastructure.ControllerActionInvoker.Next(State& next, Scope& scope, Object& state, Boolean& isCompleted)
   at Microsoft.AspNetCore.Mvc.Infrastructure.ControllerActionInvoker.InvokeInnerFilterAsync()
--- End of stack trace from previous location where exception was thrown ---
   at Microsoft.AspNetCore.Mvc.Infrastructure.ResourceInvoker.<InvokeFilterPipelineAsync>g__Awaited|19_0(ResourceInvoker invoker, Task lastTask, State next, Scope scope, Object state, Boolean isCompleted)
   at Microsoft.AspNetCore.Mvc.Infrastructure.ResourceInvoker.<InvokeAsync>g__Awaited|17_0(ResourceInvoker invoker, Task task, IDisposable scope)
   at Microsoft.AspNetCore.Routing.EndpointMiddleware.<Invoke>g__AwaitRequestTask|6_0(Endpoint endpoint, Task requestTask, ILogger logger)
   at Hzdtf.Utility.AspNet.Core.ExceptionHandle.ApiExceptionHandleMiddleware.InvokeAsync(HttpContext context) in C:\AndyData\MyProject\Hzdtf.FoundationFramework\Common\Hzdtf.Utility.AspNet.Core\ExceptionHandle\ApiExceptionHandleMiddleware.cs:line 59
时间:2020-05-14 01:09:42.732
级别:error
来源:ApiExceptionHandleMiddleware
消息:这是一个测试异常
异常:Message:这是一个测试异常.Description:System.Exception: 这是一个测试异常
   at Hzdtf.WebTest3._1.Core.Controllers.DefaultController.Get() in C:\AndyData\MyProject\Hzdtf.FoundationFramework\WebDemoCore\Hzdtf.WebTest3.1.Core\Controllers\DefaultController.cs:line 18
   at lambda_method(Closure , Object , Object[] )
   at Microsoft.Extensions.Internal.ObjectMethodExecutor.Execute(Object target, Object[] parameters)
   at Microsoft.AspNetCore.Mvc.Infrastructure.ActionMethodExecutor.SyncObjectResultExecutor.Execute(IActionResultTypeMapper mapper, ObjectMethodExecutor executor, Object controller, Object[] arguments)
   at Microsoft.AspNetCore.Mvc.Infrastructure.ControllerActionInvoker.InvokeActionMethodAsync()
   at Microsoft.AspNetCore.Mvc.Infrastructure.ControllerActionInvoker.Next(State& next, Scope& scope, Object& state, Boolean& isCompleted)
   at Microsoft.AspNetCore.Mvc.Infrastructure.ControllerActionInvoker.InvokeNextActionFilterAsync()
--- End of stack trace from previous location where exception was thrown ---
   at Microsoft.AspNetCore.Mvc.Infrastructure.ControllerActionInvoker.Rethrow(ActionExecutedContextSealed context)
   at Microsoft.AspNetCore.Mvc.Infrastructure.ControllerActionInvoker.Next(State& next, Scope& scope, Object& state, Boolean& isCompleted)
   at Microsoft.AspNetCore.Mvc.Infrastructure.ControllerActionInvoker.InvokeInnerFilterAsync()
--- End of stack trace from previous location where exception was thrown ---
   at Microsoft.AspNetCore.Mvc.Infrastructure.ResourceInvoker.<InvokeFilterPipelineAsync>g__Awaited|19_0(ResourceInvoker invoker, Task lastTask, State next, Scope scope, Object state, Boolean isCompleted)
   at Microsoft.AspNetCore.Mvc.Infrastructure.ResourceInvoker.<InvokeAsync>g__Awaited|17_0(ResourceInvoker invoker, Task task, IDisposable scope)
   at Microsoft.AspNetCore.Routing.EndpointMiddleware.<Invoke>g__AwaitRequestTask|6_0(Endpoint endpoint, Task requestTask, ILogger logger)
   at Hzdtf.Utility.AspNet.Core.ExceptionHandle.ApiExceptionHandleMiddleware.InvokeAsync(HttpContext context) in C:\AndyData\MyProject\Hzdtf.FoundationFramework\Common\Hzdtf.Utility.AspNet.Core\ExceptionHandle\ApiExceptionHandleMiddleware.cs:line 59
时间:2020-05-14 01:10:45.362
级别:error
来源:ApiExceptionHandleMiddleware
消息:这是一个测试异常
异常:Message:这是一个测试异常.Description:System.Exception: 这是一个测试异常
   at Hzdtf.WebTest3._1.Core.Controllers.DefaultController.Get() in C:\AndyData\MyProject\Hzdtf.FoundationFramework\WebDemoCore\Hzdtf.WebTest3.1.Core\Controllers\DefaultController.cs:line 18
   at lambda_method(Closure , Object , Object[] )
   at Microsoft.Extensions.Internal.ObjectMethodExecutor.Execute(Object target, Object[] parameters)
   at Microsoft.AspNetCore.Mvc.Infrastructure.ActionMethodExecutor.SyncObjectResultExecutor.Execute(IActionResultTypeMapper mapper, ObjectMethodExecutor executor, Object controller, Object[] arguments)
   at Microsoft.AspNetCore.Mvc.Infrastructure.ControllerActionInvoker.InvokeActionMethodAsync()
   at Microsoft.AspNetCore.Mvc.Infrastructure.ControllerActionInvoker.Next(State& next, Scope& scope, Object& state, Boolean& isCompleted)
   at Microsoft.AspNetCore.Mvc.Infrastructure.ControllerActionInvoker.InvokeNextActionFilterAsync()
--- End of stack trace from previous location where exception was thrown ---
   at Microsoft.AspNetCore.Mvc.Infrastructure.ControllerActionInvoker.Rethrow(ActionExecutedContextSealed context)
   at Microsoft.AspNetCore.Mvc.Infrastructure.ControllerActionInvoker.Next(State& next, Scope& scope, Object& state, Boolean& isCompleted)
   at Microsoft.AspNetCore.Mvc.Infrastructure.ControllerActionInvoker.InvokeInnerFilterAsync()
--- End of stack trace from previous location where exception was thrown ---
   at Microsoft.AspNetCore.Mvc.Infrastructure.ResourceInvoker.<InvokeFilterPipelineAsync>g__Awaited|19_0(ResourceInvoker invoker, Task lastTask, State next, Scope scope, Object state, Boolean isCompleted)
   at Microsoft.AspNetCore.Mvc.Infrastructure.ResourceInvoker.<InvokeAsync>g__Awaited|17_0(ResourceInvoker invoker, Task task, IDisposable scope)
   at Microsoft.AspNetCore.Routing.EndpointMiddleware.<Invoke>g__AwaitRequestTask|6_0(Endpoint endpoint, Task requestTask, ILogger logger)
   at Hzdtf.Utility.AspNet.Core.ExceptionHandle.ApiExceptionHandleMiddleware.InvokeAsync(HttpContext context) in C:\AndyData\MyProject\Hzdtf.FoundationFramework\Common\Hzdtf.Utility.AspNet.Core\ExceptionHandle\ApiExceptionHandleMiddleware.cs:line 59
时间:2020-05-14 01:10:47.458
级别:error
来源:ApiExceptionHandleMiddleware
消息:这是一个测试异常
异常:Message:这是一个测试异常.Description:System.Exception: 这是一个测试异常
   at Hzdtf.WebTest3._1.Core.Controllers.DefaultController.Get() in C:\AndyData\MyProject\Hzdtf.FoundationFramework\WebDemoCore\Hzdtf.WebTest3.1.Core\Controllers\DefaultController.cs:line 18
   at lambda_method(Closure , Object , Object[] )
   at Microsoft.Extensions.Internal.ObjectMethodExecutor.Execute(Object target, Object[] parameters)
   at Microsoft.AspNetCore.Mvc.Infrastructure.ActionMethodExecutor.SyncObjectResultExecutor.Execute(IActionResultTypeMapper mapper, ObjectMethodExecutor executor, Object controller, Object[] arguments)
   at Microsoft.AspNetCore.Mvc.Infrastructure.ControllerActionInvoker.InvokeActionMethodAsync()
   at Microsoft.AspNetCore.Mvc.Infrastructure.ControllerActionInvoker.Next(State& next, Scope& scope, Object& state, Boolean& isCompleted)
   at Microsoft.AspNetCore.Mvc.Infrastructure.ControllerActionInvoker.InvokeNextActionFilterAsync()
--- End of stack trace from previous location where exception was thrown ---
   at Microsoft.AspNetCore.Mvc.Infrastructure.ControllerActionInvoker.Rethrow(ActionExecutedContextSealed context)
   at Microsoft.AspNetCore.Mvc.Infrastructure.ControllerActionInvoker.Next(State& next, Scope& scope, Object& state, Boolean& isCompleted)
   at Microsoft.AspNetCore.Mvc.Infrastructure.ControllerActionInvoker.InvokeInnerFilterAsync()
--- End of stack trace from previous location where exception was thrown ---
   at Microsoft.AspNetCore.Mvc.Infrastructure.ResourceInvoker.<InvokeFilterPipelineAsync>g__Awaited|19_0(ResourceInvoker invoker, Task lastTask, State next, Scope scope, Object state, Boolean isCompleted)
   at Microsoft.AspNetCore.Mvc.Infrastructure.ResourceInvoker.<InvokeAsync>g__Awaited|17_0(ResourceInvoker invoker, Task task, IDisposable scope)
   at Microsoft.AspNetCore.Routing.EndpointMiddleware.<Invoke>g__AwaitRequestTask|6_0(Endpoint endpoint, Task requestTask, ILogger logger)
   at Hzdtf.Utility.AspNet.Core.ExceptionHandle.ApiExceptionHandleMiddleware.InvokeAsync(HttpContext context) in C:\AndyData\MyProject\Hzdtf.FoundationFramework\Common\Hzdtf.Utility.AspNet.Core\ExceptionHandle\ApiExceptionHandleMiddleware.cs:line 59
时间:2020-05-14 01:11:47.356
级别:error
来源:ApiExceptionHandleMiddleware
消息:这是一个测试异常
异常:Message:这是一个测试异常.Description:System.Exception: 这是一个测试异常
   at Hzdtf.WebTest3._1.Core.Controllers.DefaultController.Get() in C:\AndyData\MyProject\Hzdtf.FoundationFramework\WebDemoCore\Hzdtf.WebTest3.1.Core\Controllers\DefaultController.cs:line 18
   at lambda_method(Closure , Object , Object[] )
   at Microsoft.Extensions.Internal.ObjectMethodExecutor.Execute(Object target, Object[] parameters)
   at Microsoft.AspNetCore.Mvc.Infrastructure.ActionMethodExecutor.SyncObjectResultExecutor.Execute(IActionResultTypeMapper mapper, ObjectMethodExecutor executor, Object controller, Object[] arguments)
   at Microsoft.AspNetCore.Mvc.Infrastructure.ControllerActionInvoker.InvokeActionMethodAsync()
   at Microsoft.AspNetCore.Mvc.Infrastructure.ControllerActionInvoker.Next(State& next, Scope& scope, Object& state, Boolean& isCompleted)
   at Microsoft.AspNetCore.Mvc.Infrastructure.ControllerActionInvoker.InvokeNextActionFilterAsync()
--- End of stack trace from previous location where exception was thrown ---
   at Microsoft.AspNetCore.Mvc.Infrastructure.ControllerActionInvoker.Rethrow(ActionExecutedContextSealed context)
   at Microsoft.AspNetCore.Mvc.Infrastructure.ControllerActionInvoker.Next(State& next, Scope& scope, Object& state, Boolean& isCompleted)
   at Microsoft.AspNetCore.Mvc.Infrastructure.ControllerActionInvoker.InvokeInnerFilterAsync()
--- End of stack trace from previous location where exception was thrown ---
   at Microsoft.AspNetCore.Mvc.Infrastructure.ResourceInvoker.<InvokeFilterPipelineAsync>g__Awaited|19_0(ResourceInvoker invoker, Task lastTask, State next, Scope scope, Object state, Boolean isCompleted)
   at Microsoft.AspNetCore.Mvc.Infrastructure.ResourceInvoker.<InvokeAsync>g__Awaited|17_0(ResourceInvoker invoker, Task task, IDisposable scope)
   at Microsoft.AspNetCore.Routing.EndpointMiddleware.<Invoke>g__AwaitRequestTask|6_0(Endpoint endpoint, Task requestTask, ILogger logger)
   at Hzdtf.Utility.AspNet.Core.ExceptionHandle.ApiExceptionHandleMiddleware.InvokeAsync(HttpContext context) in C:\AndyData\MyProject\Hzdtf.FoundationFramework\Common\Hzdtf.Utility.AspNet.Core\ExceptionHandle\ApiExceptionHandleMiddleware.cs:line 59
时间:2020-05-14 07:01:08.539
级别:error
来源:ApiExceptionHandleMiddleware
消息:这是一个测试异常
异常:Message:这是一个测试异常.Description:System.Exception: 这是一个测试异常
   at Hzdtf.WebTest3._1.Core.Controllers.DefaultController.Get() in C:\AndyData\MyProject\Hzdtf.FoundationFramework\WebDemoCore\Hzdtf.WebTest3.1.Core\Controllers\DefaultController.cs:line 18
   at lambda_method(Closure , Object , Object[] )
   at Microsoft.Extensions.Internal.ObjectMethodExecutor.Execute(Object target, Object[] parameters)
   at Microsoft.AspNetCore.Mvc.Infrastructure.ActionMethodExecutor.SyncObjectResultExecutor.Execute(IActionResultTypeMapper mapper, ObjectMethodExecutor executor, Object controller, Object[] arguments)
   at Microsoft.AspNetCore.Mvc.Infrastructure.ControllerActionInvoker.InvokeActionMethodAsync()
   at Microsoft.AspNetCore.Mvc.Infrastructure.ControllerActionInvoker.Next(State& next, Scope& scope, Object& state, Boolean& isCompleted)
   at Microsoft.AspNetCore.Mvc.Infrastructure.ControllerActionInvoker.InvokeNextActionFilterAsync()
--- End of stack trace from previous location where exception was thrown ---
   at Microsoft.AspNetCore.Mvc.Infrastructure.ControllerActionInvoker.Rethrow(ActionExecutedContextSealed context)
   at Microsoft.AspNetCore.Mvc.Infrastructure.ControllerActionInvoker.Next(State& next, Scope& scope, Object& state, Boolean& isCompleted)
   at Microsoft.AspNetCore.Mvc.Infrastructure.ControllerActionInvoker.InvokeInnerFilterAsync()
--- End of stack trace from previous location where exception was thrown ---
   at Microsoft.AspNetCore.Mvc.Infrastructure.ResourceInvoker.<InvokeFilterPipelineAsync>g__Awaited|19_0(ResourceInvoker invoker, Task lastTask, State next, Scope scope, Object state, Boolean isCompleted)
   at Microsoft.AspNetCore.Mvc.Infrastructure.ResourceInvoker.<InvokeAsync>g__Awaited|17_0(ResourceInvoker invoker, Task task, IDisposable scope)
   at Microsoft.AspNetCore.Routing.EndpointMiddleware.<Invoke>g__AwaitRequestTask|6_0(Endpoint endpoint, Task requestTask, ILogger logger)
   at Hzdtf.Utility.AspNet.Core.ExceptionHandle.ApiExceptionHandleMiddleware.InvokeAsync(HttpContext context) in C:\AndyData\MyProject\Hzdtf.FoundationFramework\Common\Hzdtf.Utility.AspNet.Core\ExceptionHandle\ApiExceptionHandleMiddleware.cs:line 59
时间:2020-05-14 07:01:59.150
级别:error
来源:ApiExceptionHandleMiddleware
消息:这是一个测试异常
异常:Message:这是一个测试异常.Description:System.Exception: 这是一个测试异常
   at Hzdtf.WebTest3._1.Core.Controllers.DefaultController.Get() in C:\AndyData\MyProject\Hzdtf.FoundationFramework\WebDemoCore\Hzdtf.WebTest3.1.Core\Controllers\DefaultController.cs:line 18
   at lambda_method(Closure , Object , Object[] )
   at Microsoft.Extensions.Internal.ObjectMethodExecutor.Execute(Object target, Object[] parameters)
   at Microsoft.AspNetCore.Mvc.Infrastructure.ActionMethodExecutor.SyncObjectResultExecutor.Execute(IActionResultTypeMapper mapper, ObjectMethodExecutor executor, Object controller, Object[] arguments)
   at Microsoft.AspNetCore.Mvc.Infrastructure.ControllerActionInvoker.InvokeActionMethodAsync()
   at Microsoft.AspNetCore.Mvc.Infrastructure.ControllerActionInvoker.Next(State& next, Scope& scope, Object& state, Boolean& isCompleted)
   at Microsoft.AspNetCore.Mvc.Infrastructure.ControllerActionInvoker.InvokeNextActionFilterAsync()
--- End of stack trace from previous location where exception was thrown ---
   at Microsoft.AspNetCore.Mvc.Infrastructure.ControllerActionInvoker.Rethrow(ActionExecutedContextSealed context)
   at Microsoft.AspNetCore.Mvc.Infrastructure.ControllerActionInvoker.Next(State& next, Scope& scope, Object& state, Boolean& isCompleted)
   at Microsoft.AspNetCore.Mvc.Infrastructure.ControllerActionInvoker.InvokeInnerFilterAsync()
--- End of stack trace from previous location where exception was thrown ---
   at Microsoft.AspNetCore.Mvc.Infrastructure.ResourceInvoker.<InvokeFilterPipelineAsync>g__Awaited|19_0(ResourceInvoker invoker, Task lastTask, State next, Scope scope, Object state, Boolean isCompleted)
   at Microsoft.AspNetCore.Mvc.Infrastructure.ResourceInvoker.<InvokeAsync>g__Awaited|17_0(ResourceInvoker invoker, Task task, IDisposable scope)
   at Microsoft.AspNetCore.Routing.EndpointMiddleware.<Invoke>g__AwaitRequestTask|6_0(Endpoint endpoint, Task requestTask, ILogger logger)
   at Hzdtf.Utility.AspNet.Core.ExceptionHandle.ApiExceptionHandleMiddleware.InvokeAsync(HttpContext context) in C:\AndyData\MyProject\Hzdtf.FoundationFramework\Common\Hzdtf.Utility.AspNet.Core\ExceptionHandle\ApiExceptionHandleMiddleware.cs:line 59
